Workbook

Sheet Сountries
A1: # | B1: region | C1: subregion | D1: 3-ISO | E1: 2-ISO | F1: calling code | G1: flag | H1: country_name | I1: capital | J1: population 2025 | K1: world share | L1: land area (Km²) | M1: density (P/Km²) | N1: GDP (nominal, 2023) | O1: GDP per capita 2023 | P1: Share of World GDP 2023 | Q1: GDP (nominal, 2024 million USD) | R1: Yearly Water Used (m³, thousand of litres) | S1: Daily Water Used Per Capita (litres) | V1: country_name | W1: region | X1: subregion | Y1: 2-ISO | Z1: flag
A2: 1 | B2: Asia | C2: Southern Asia | D2: IND | E2: IN | F2: 91 | G2: 🇮🇳 | H2: India | I2: New Delhi | J2: 1463865525 | K2: 0.1778 | L2: 2973190 | M2: 492 | N2: 3567550000000 | O2: 2481 | P2: 0.0336 | Q2: 3912686 | R2: 761000000000 | S2: 1677 | V2: India | W2: Asia | X2: Southern Asia | Y2: IN | Z2: 🇮🇳
A3: 2 | B3: Asia | C3: Eastern Asia | D3: CHN | E3: CN | F3: 86 | G3: 🇨🇳 | H3: China | I3: Beijing | J3: 1416096094 | K3: 0.172 | L3: 9388211 | M3: 151 | N3: 17794800000000 | O3: 12509 | P3: 0.1676 | Q3: 18743803 | R3: 598100000000 | S3: 1174 | V3: China | W3: Asia | X3: Eastern Asia | Y3: CN | Z3: 🇨🇳
A4: 3 | B4: America | C4: Northern America | D4: USA | E4: US | F4: 1 | G4: 🇺🇸 | H4: United States | I4: Washington D.C. | J4: 347275807 | K4: 0.0422 | L4: 9147420 | M4: 38 | N4: 27720700000000 | O4: 80706 | P4: 0.2611 | Q4: 29184890 | R4: 444300000000 | S4: 3732 | V4: United States | W4: America | X4: Northern America | Y4: US | Z4: 🇺🇸
A5: 4 | B5: Asia | C5: South-Eastern Asia | D5: IDN | E5: ID | F5: 62 | G5: 🇮🇩 | H5: Indonesia | I5: Jakarta[9] | J5: 285721236 | K5: 0.0347 | L5: 1811570 | M5: 158 | N5: 1371170000000 | O5: 4876 | P5: 0.0129 | Q5: 1396300 | R5: 222600000000 | S5: 2305 | V5: Indonesia | W5: Asia | X5: South-Eastern Asia | Y5: ID | Z5: 🇮🇩
A6: 5 | B6: Asia | C6: Southern Asia | D6: PAK | E6: PK | F6: 92 | G6: 🇵🇰 | H6: Pakistan | I6: Islamabad | J6: 255219554 | K6: 0.031 | L6: 770880 | M6: 331 | N6: 337912000000 | O6: 1365 | P6: 0.0032 | Q6: 2024 | R6: 183500000000 | S6: 2653 | V6: Pakistan | W6: Asia | X6: Southern Asia | Y6: PK | Z6: 🇵🇰
A7: 6 | B7: Africa | C7: Western Africa | D7: NGA | E7: NG | F7: 234 | G7: 🇳🇬 | H7: Nigeria | I7: Abuja | J7: 237527782 | K7: 0.0289 | L7: 910770 | M7: 261 | N7: 363846000000 | O7: 1597 | P7: 0.0034 | Q7: 187760 | R7: 12470000000 | S7: 205 | V7: Nigeria | W7: Africa | X7: Western Africa | Y7: NG | Z7: 🇳🇬
A8: 7 | B8: America | C8: South America | D8: BRA | E8: BR | F8: 55 | G8: 🇧🇷 | H8: Brazil | I8: Brasilia | J8: 212812405 | K8: 0.0259 | L8: 8358140 | M8: 25 | N8: 2173670000000 | O8: 10295 | P8: 0.0205 | Q8: 2179412 | R8: 63500000000 | S8: 856 | V8: Brazil | W8: America | X8: South America | Y8: BR | Z8: 🇧🇷
A9: 8 | B9: Asia | C9: Southern Asia | D9: BGD | E9: BD | F9: 880 | G9: 🇧🇩 | H9: Bangladesh | I9: Dhaka | J9: 175686899 | K9: 0.0213 | L9: 130170 | M9: 1350 | N9: 437415000000 | O9: 2551 | P9: 0.0041 | Q9: 450119 | R9: 35870000000 | S9: 657 | V9: Bangladesh | W9: Asia | X9: Southern Asia | Y9: BD | Z9: 🇧🇩
A10: 9 | B10: Europe | C10: Eastern Europe | D10: RUS | E10: RU | F10: 7 | G10: 🇷🇺 | H10: Russian Federation | I10: Moscow | J10: 143997393 | K10: 0.0175 | L10: 16376870 | M10: 9 | N10: 2021420000000 | O10: 13899 | P10: 0.019 | Q10: 2173836 | R10: 69500000000 | S10: 1306 | V10: Russian Federation | W10: Europe | X10: Eastern Europe | Y10: RU | Z10: 🇷🇺
A11: 10 | B11: Africa | C11: Eastern Africa | D11: ETH | E11: ET | F11: 251 | G11: 🇪🇹 | H11: Ethiopia | I11: Addis Ababa | J11: 135472051 | K11: 0.0165 | L11: 1000000 | M11: 135 | N11: 163698000000 | O11: 1272 | P11: 0.0015 | Q11: 163698 | R11: 10550000000 | S11: 271 | V11: Ethiopia | W11: Africa | X11: Eastern Africa | Y11: ET | Z11: 🇪🇹
A12: 11 | B12: America | C12: Central America | D12: MEX | E12: MX | F12: 52 | G12: 🇲🇽 | H12: Mexico | I12: Mexico City | J12: 131946900 | K12: 0.016 | L12: 1943950 | M12: 68 | N12: 1789110000000 | O12: 13790 | P12: 0.0169 | Q12: 1852723 | R12: 86580000000 | S12: 1940 | V12: Mexico | W12: America | X12: Central America | Y12: MX | Z12: 🇲🇽
A13: 12 | B13: Asia | C13: Eastern Asia | D13: JPN | E13: JP | F13: 81 | G13: 🇯🇵 | H13: Japan | I13: Tokyo | J13: 123103479 | K13: 0.015 | L13: 364555 | M13: 338 | N13: 4204490000000 | O13: 33806 | P13: 0.0396 | Q13: 4026211 | R13: 81450000000 | S13: 1741 | V13: Japan | W13: Asia | X13: Eastern Asia | Y13: JP | Z13: 🇯🇵
... A37: 36 | B37: Asia | C37: Southern Asia | D37: AFG | E37: AF | F37: 93 | G37: 🇦🇫 | H37: Afghanistan | I37: Kabul | J37: 43844111 | K37: 0.0053 | L37: 652860 | M37: 67 | N37: 17233051620 | O37: 416 | P37: 0.00016 | Q37: 2023 | R37: 20280000000 | S37: 2760 | V37: Afghanistan | W37: Asia | X37: Southern Asia | Y37: AF | Z37: 🇦🇫
A38: 37 | B38: Asia | C38: Western Asia | D38: YEM | E38: YE | F38: 967 | G38: 🇾🇪 | H38: Yemen | I38: Sana'a | J38: 41773878 | K38: 0.0051 | L38: 527970 | M38: 79 | N38: #N/A | O38: #N/A | P38: #N/A | Q38: — | R38: 3565000000 | S38: 429 | V38: Yemen | W38: Asia | X38: Western Asia | Y38: YE | Z38: 🇾🇪
A39: 38 | B39: America | C39: Northern America | D39: CAN | E39: CA | F39: 1 | G39: 🇨🇦 | H39: Canada | I39: Ottawa | J39: 40126723 | K39: 0.0049 | L39: 9093510 | M39: 4 | N39: 2142470000000 | O39: 54517 | P39: 0.0202 | Q39: 2241253 | R39: 35730000000 | S39: 2722 | V39: Canada | W39: America | X39: Northern America | Y39: CA | Z39: 🇨🇦
A40: 39 | B40: Africa | C40: Middle Africa | D40: AGO | E40: AO | F40: 244 | G40: 🇦🇴 | H40: Angola | I40: Luanda | J40: 39040039 | K40: 0.0047 | L40: 1246700 | M40: 31 | N40: 84824654482 | O40: 2308 | P40: 0.0008 | Q40: 80397 | R40: 705800000 | S40: 100 | V40: Angola | W40: Africa | X40: Middle Africa | Y40: AO | Z40: 🇦🇴
A41: 40 | B41: Europe | C41: Eastern Europe | D41: UKR | E41: UA | F41: 380 | G41: 🇺🇦 | H41: Ukraine | I41: Kyiv | J41: 38980376 | K41: 0.0047 | L41: 579320 | M41: 67 | N41: 178757000000 | O41: 4737 | P41: 0.0017 | Q41: 190741 | R41: 9862000000 | S41: 592 | V41: Ukraine | W41: Europe | X41: Eastern Europe | Y41: UA | Z41: 🇺🇦
A42: 41 | B42: Africa | C42: Northern Africa | D42: MAR | E42: MA | F42: 212 | G42: 🇲🇦 | H42: Morocco | I42: Rabat | J42: 38430770 | K42: 0.0047 | L42: 446300 | M42: 86 | N42: 144417000000 | O42: 3829 | P42: 0.0014 | Q42: 154431 | R42: 10430000000 | S42: 880 | V42: Morocco | W42: Africa | X42: Northern Africa | Y42: MA | Z42: 🇲🇦
A43: 42 | B43: Europe | C43: Eastern Europe | D43: POL | E43: PL | F43: 48 | G43: 🇵🇱 | H43: Poland | I43: Warsaw | J43: 38140910 | K43: 0.0046 | L43: 306230 | M43: 125 | N43: 809201000000 | O43: 20876 | P43: 0.0076 | Q43: 914696 | R43: 10580000000 | S43: 758 | V43: Poland | W43: Europe | X43: Eastern Europe | Y43: PL | Z43: 🇵🇱
A44: 43 | B44: Asia | C44: Central Asia | D44: UZB | E44: UZ | F44: 998 | G44: 🇺🇿 | H44: Uzbekistan | I44: Tashkent | J44: 37053428 | K44: 0.0045 | L44: 425400 | M44: 87 | N44: 101592000000 | O44: 2850 | P44: 0.00096 | Q44: 114965 | R44: 54560000000 | S44: 4778 | V44: Uzbekistan | W44: Asia | X44: Central Asia | Y44: UZ | Z44: 🇺🇿
A45: 44 | B45: Asia | C45: South-Eastern Asia | D45: MYS | E45: MY | F45: 60 | G45: 🇲🇾 | H45: Malaysia | I45: Kuala Lumpur | J45: 35977838 | K45: 0.0044 | L45: 328550 | M45: 110 | N45: 399705000000 | O45: 11379 | P45: 0.0038 | Q45: 421972 | R45: 11200000000 | S45: 1188 | V45: Malaysia | W45: Asia | X45: South-Eastern Asia | Y45: MY | Z45: 🇲🇾
A46: 45 | B46: Africa | C46: Eastern Africa | D46: MOZ | E46: MZ | F46: 258 | G46: 🇲🇿 | H46: Mozambique | I46: Maputo | J46: 35631653 | K46: 0.0043 | L46: 786380 | M46: 45 | N46: 20954220984 | O46: 623 | P46: 0.0002 | Q46: 22417 | R46: 1473000000 | S46: 152 | V46: Mozambique | W46: Africa | X46: Eastern Africa | Y46: MZ | Z46: 🇲🇿
A47: 46 | B47: Africa | C47: Western Africa | D47: GHA | E47: GH | F47: 233 | G47: 🇬🇭 | H47: Ghana | I47: Accra | J47: 35064272 | K47: 0.0043 | L47: 227540 | M47: 154 | N47: 76370396722 | O47: 2260 | P47: 0.00072 | Q47: 82825 | R47: 982000000 | S47: 137 | V47: Ghana | W47: Africa | X47: Western Africa | Y47: GH | Z47: 🇬🇭
A48: 47 | B48: America | C48: South America | D48: PER | E48: PE | F48: 51 | G48: 🇵🇪 | H48: Peru | I48: Lima | J48: 34576665 | K48: 0.0042 | L48: 1280000 | M48: 27 | N48: 267603000000 | O48: 7907 | P48: 0.0025 | Q48: 289222 | R48: 13660000000 | S48: 1303 | V48: Peru | W48: America | X48: South America | Y48: PE | Z48: 🇵🇪
A49: 48 | B49: Asia | C49: Western Asia | D49: SAU | E49: SA | F49: 966 | G49: 🇸🇦 | H49: Saudi Arabia | I49: Riyadh | J49: 34566328 | K49: 0.0042 | L49: 2149690 | M49: 16 | N49: 1067580000000 | O49: 32094 | P49: 0.0101 | Q49: 1237530 | R49: 23350000000 | S49: 2078 | V49: Saudi Arabia | W49: Asia | X49: Western Asia | Y49: SA | Z49: 🇸🇦
A50: 49 | B50: Africa | C50: Eastern Africa | D50: MDG | E50: MG | F50: 261 | G50: 🇲🇬 | H50: Madagascar | I50: Antananarivo | J50: 32740678 | K50: 0.004 | L50: 581795 | M50: 56 | N50: 15790113247 | O50: 506 | P50: 0.00015 | Q50: 17421 | R50: 13560000000 | S50: 1883 | V50: Madagascar | W50: Africa | X50: Eastern Africa | Y50: MG | Z50: 🇲🇬
... A53: 52 | B53: Asia | C53: Southern Asia | D53: NPL | E53: NP | F53: 977 | G53: 🇳🇵 | H53: Nepal | I53: Kathmandu | J53: 29618118 | K53: 0.0036 | L53: 143350 | M53: 207 | N53: 40908073367 | O53: 1378 | P53: 0.00039 | Q53: 42914 | R53: 9497000000 | S53: 979 | V53: Nepal | W53: Asia | X53: Southern Asia | Y53: NP | Z53: 🇳🇵
A54: 53 | B54: America | C54: South America | D54: VEN | E54: VE | F54: 58 | G54: 🇻🇪 | H54: Venezuela | I54: Caracas | J54: 28516896 | K54: 0.0035 | L54: 882050 | M54: 32 | N54: #N/A | O54: #N/A | P54: #N/A | Q54: — | R54: 22630000000 | S54: 2242 | V54: Venezuela | W54: America | X54: South America | Y54: VE | Z54: 🇻🇪
A55: 54 | B55: Africa | C55: Western Africa | D55: NER | E55: NE | F55: 227 | G55: 🇳🇪 | H55: Niger | I55: Niamey | J55: 27917831 | K55: 0.0034 | L55: 1266700 | M55: 22 | N55: 16819170421 | O55: 643 | P55: 0.00016 | Q55: 19538 | R55: 1747000000 | S55: 231 | V55: Niger | W55: Africa | X55: Western Africa | Y55: NE | Z55: 🇳🇪
A56: 55 | B56: Australia and New Zealand | C56: Australia and New Zealand | D56: AUS | E56: AU | F56: 61 | G56: 🇦🇺 | H56: Australia | I56: Canberra | J56: 26974026 | K56: 0.0033 | L56: 7682300 | M56: 4 | N56: 1728060000000 | O56: 65330 | P56: 0.0163 | Q56: 1752193 | R56: 16130000000 | S56: 1816 | V56: Australia | W56: Australia and New Zealand | X56: Australia and New Zealand | Y56: AU | Z56: 🇦🇺
A57: 56 | B57: Asia | C57: Eastern Asia | D57: PRK | E57: KP | F57: 850 | G57: 🇰🇵 | H57: North Korea | I57: Pyongyang | J57: 26571036 | K57: 0.0032 | L57: 120410 | M57: 221 | N57: #N/A | O57: #N/A | P57: #N/A | Q57: 16447 | R57: 8658000000 | S57: 972 | V57: North Korea | W57: Asia | X57: Eastern Asia | Y57: KP | Z57: 🇰🇵
A58: 57 | B58: Asia | C58: Western Asia | D58: SYR | E58: SY | F58: 963 | G58: 🇸🇾 | H58: Syria | I58: Damascus | J58: 25620427 | K58: 0.0031 | L58: 183630 | M58: 140 | N58: #N/A | O58: #N/A | P58: #N/A | Q58: 2023 | R58: 16760000000 | S58: 2441 | V58: Syria | W58: Asia | X58: Western Asia | Y58: SY | Z58: 🇸🇾
A59: 58 | B59: Africa | C59: Western Africa | D59: MLI | E59: ML | F59: 223 | G59: 🇲🇱 | H59: Mali | I59: Bamako | J59: 25198821 | K59: 0.0031 | L59: 1220190 | M59: 21 | N59: 20661794596 | O59: 869 | P59: 0.00019 | Q59: 26588 | R59: 5186000000 | S59: 1016 | V59: Mali | W59: Africa | X59: Western Africa | Y59: ML | Z59: 🇲🇱
A60: 59 | B60: Africa | C60: Western Africa | D60: BFA | E60: BF | F60: 226 | G60: 🇧🇫 | H60: Burkina Faso | I60: Ouagadougou | J60: 24074580 | K60: 0.0029 | L60: 273600 | M60: 88 | N60: 20324617845 | O60: 883 | P60: 0.00019 | Q60: 23250 | R60: 818000000 | S60: 161 | V60: Burkina Faso | W60: Africa | X60: Western Africa | Y60: BF | Z60: 🇧🇫
A61: 60 | B61: Asia | C61: Southern Asia | D61: LKA | E61: LK | F61: 94 | G61: 🇱🇰 | H61: Sri Lanka | I61: Sri Jayawardenapura Kotte | J61: 23229470 | K61: 0.0028 | L61: 62710 | M61: 370 | N61: 84356863744 | O61: 3672 | P61: 0.00079 | Q61: 2024 | R61: 12950000000 | S61: 1755 | V61: Sri Lanka | W61: Asia | X61: Southern Asia | Y61: LK | Z61: 🇱🇰
A62: 61 | B62: Africa | C62: Eastern Africa | D62: MWI | E62: MW | F62: 265 | G62: 🇲🇼 | H62: Malawi | I62: Lilongwe | J62: 22216120 | K62: 0.0027 | L62: 94280 | M62: 236 | N62: 12712150082 | O62: 602 | P62: 0.00012 | Q62: 11009 | R62: 1357000000 | S62: 290 | V62: Malawi | W62: Africa | X62: Eastern Africa | Y62: MW | Z62: 🇲🇼
A63: 62 | B63: Africa | C63: Eastern Africa | D63: ZMB | E63: ZM | F63: 260 | G63: 🇿🇲 | H63: Zambia | I63: Lusaka | J63: 21913874 | K63: 0.0027 | L63: 743390 | M63: 29 | N63: 27577956471 | O63: 1331 | P63: 0.00026 | Q63: 26326 | R63: 1572000000 | S63: 404 | V63: Zambia | W63: Africa | X63: Eastern Africa | Y63: ZM | Z63: 🇿🇲
A64: 63 | B64: Africa | C64: Middle Africa | D64: TCD | E64: TD | F64: 235 | G64: 🇹🇩 | H64: Chad | I64: N'Djamena | J64: 21003705 | K64: 0.0026 | L64: 1259200 | M64: 17 | N64: 13149325362 | O64: 681 | P64: 0.00012 | Q64: 20626 | R64: 879600000 | S64: 233 | V64: Chad | W64: Africa | X64: Middle Africa | Y64: TD | Z64: 🇹🇩
A65: 64 | B65: Asia | C65: Central Asia | D65: KAZ | E65: KZ | F65: 7 | G65: 🇰🇿 | H65: Kazakhstan | I65: Astana | J65: 20843754 | K65: 0.0025 | L65: 2699700 | M65: 8 | N65: 262642000000 | O65: 12919 | P65: 0.0025 | Q65: 288406 | R65: 22770000000 | S65: 3397 | V65: Kazakhstan | W65: Asia | X65: Central Asia | Y65: KZ | Z65: 🇰🇿
...

Sheet all_countries
A1: # | B1: region | C1: subregion | D1: Country | E1: Flags | F1: Population 2025 | G1: Yearly Change | H1: Net Change | I1: Density (P/Km²) | J1: Land Area (Km²) | K1: Migrants (net) | L1: Fert. Rate | M1: Median Age | N1: Urban Pop % | O1: World Share | R1: region | S1: subregion | T1: Flags
A2: 1 | B2: Asia | C2: Southern Asia | D2: India | E2: 🇮🇳 | F2: 1463865525 | G2: 0.0089 | H2: 12929734 | I2: 492 | J2: 2973190 | K2: −495,753 | L2: 1.94 | M2: 28.8 | N2: 0.371 | O2: 0.1778 | R2: =VLOOKUP(D2,Сountries!V:Z,2,0) -> Asia | S2: =VLOOKUP(D2,Сountries!V:Z,3,0) -> Southern Asia | T2: =VLOOKUP(D2,Сountries!V:Z,5,0) -> 🇮🇳 | U2: =E2=T2 -> TRUE
A3: 2 | B3: Asia | C3: Eastern Asia | D3: China | E3: 🇨🇳 | F3: 1416096094 | G3: −0.23% | H3: −3,225,184 | I3: 151 | J3: 9388211 | K3: −268,126 | L3: 1.02 | M3: 40.1 | N3: 0.675 | O3: 0.172 | R3: =VLOOKUP(D3,Сountries!V:Z,2,0) -> Asia | S3: =VLOOKUP(D3,Сountries!V:Z,3,0) -> Eastern Asia | T3: =VLOOKUP(D3,Сountries!V:Z,5,0) -> 🇨🇳 | U3: =E3=T3 -> TRUE
A4: 3 | B4: America | C4: Northern America | D4: United States | E4: 🇺🇸 | F4: 347275807 | G4: 0.0054 | H4: 1849236 | I4: 38 | J4: 9147420 | K4: 1230663 | L4: 1.62 | M4: 38.5 | N4: 0.828 | O4: 0.0422 | R4: =VLOOKUP(D4,Сountries!V:Z,2,0) -> America | S4: =VLOOKUP(D4,Сountries!V:Z,3,0) -> Northern America | T4: =VLOOKUP(D4,Сountries!V:Z,5,0) -> 🇺🇸 | U4: =E4=T4 -> TRUE
A5: 4 | B5: Asia | C5: South-Eastern Asia | D5: Indonesia | E5: 🇮🇩 | F5: 285721236 | G5: 0.0079 | H5: 2233305 | I5: 158 | J5: 1811570 | K5: −39,509 | L5: 2.1 | M5: 30.4 | N5: 0.596 | O5: 0.0347 | R5: =VLOOKUP(D5,Сountries!V:Z,2,0) -> Asia | S5: =VLOOKUP(D5,Сountries!V:Z,3,0) -> South-Eastern Asia | T5: =VLOOKUP(D5,Сountries!V:Z,5,0) -> 🇮🇩 | U5: =E5=T5 -> TRUE
A6: 5 | B6: Asia | C6: Southern Asia | D6: Pakistan | E6: 🇵🇰 | F6: 255219554 | G6: 0.0157 | H6: 3950390 | I6: 331 | J6: 770880 | K6: −1,235,336 | L6: 3.5 | M6: 20.6 | N6: 0.344 | O6: 0.031 | R6: =VLOOKUP(D6,Сountries!V:Z,2,0) -> Asia | S6: =VLOOKUP(D6,Сountries!V:Z,3,0) -> Southern Asia | T6: =VLOOKUP(D6,Сountries!V:Z,5,0) -> 🇵🇰 | U6: =E6=T6 -> TRUE
A7: 6 | B7: Africa | C7: Western Africa | D7: Nigeria | E7: 🇳🇬 | F7: 237527782 | G7: 0.0208 | H7: 4848304 | I7: 261 | J7: 910770 | K7: −15,258 | L7: 4.3 | M7: 18.1 | N7: 0.549 | O7: 0.0289 | R7: =VLOOKUP(D7,Сountries!V:Z,2,0) -> Africa | S7: =VLOOKUP(D7,Сountries!V:Z,3,0) -> Western Africa | T7: =VLOOKUP(D7,Сountries!V:Z,5,0) -> 🇳🇬 | U7: =E7=T7 -> TRUE
A8: 7 | B8: America | C8: South America | D8: Brazil | E8: 🇧🇷 | F8: 212812405 | G8: 0.0038 | H8: 813832 | I8: 25 | J8: 8358140 | K8: −217,283 | L8: 1.6 | M8: 34.8 | N8: 0.914 | O8: 0.0259 | R8: =VLOOKUP(D8,Сountries!V:Z,2,0) -> America | S8: =VLOOKUP(D8,Сountries!V:Z,3,0) -> South America | T8: =VLOOKUP(D8,Сountries!V:Z,5,0) -> 🇧🇷 | U8: =E8=T8 -> TRUE
A9: 8 | B9: Asia | C9: Southern Asia | D9: Bangladesh | E9: 🇧🇩 | F9: 175686899 | G9: 0.0122 | H9: 2124535 | I9: 1350 | J9: 130170 | K9: −402,100 | L9: 2.11 | M9: 26 | N9: 0.426 | O9: 0.0213 | R9: =VLOOKUP(D9,Сountries!V:Z,2,0) -> Asia | S9: =VLOOKUP(D9,Сountries!V:Z,3,0) -> Southern Asia | T9: =VLOOKUP(D9,Сountries!V:Z,5,0) -> 🇧🇩 | U9: =E9=T9 -> TRUE
A10: 9 | B10: Europe | C10: Eastern Europe | D10: Russian Federation | E10: 🇷🇺 | F10: 143997393 | G10: −0.57% | H10: −823,030 | I10: 9 | J10: 16376870 | K10: −251,822 | L10: 1.47 | M10: 40.3 | N10: 0.75 | O10: 0.0175 | R10: =VLOOKUP(D10,Сountries!V:Z,2,0) -> Europe | S10: =VLOOKUP(D10,Сountries!V:Z,3,0) -> Eastern Europe | T10: =VLOOKUP(D10,Сountries!V:Z,5,0) -> 🇷🇺 | U10: =E10=T10 -> TRUE
A11: 10 | B11: Africa | C11: Eastern Africa | D11: Ethiopia | E11: 🇪🇹 | F11: 135472051 | G11: 0.0258 | H11: 3412284 | I11: 135 | J11: 1000000 | K11: 24054 | L11: 3.81 | M11: 19.1 | N11: 0.225 | O11: 0.0165 | R11: =VLOOKUP(D11,Сountries!V:Z,2,0) -> Africa | S11: =VLOOKUP(D11,Сountries!V:Z,3,0) -> Eastern Africa | T11: =VLOOKUP(D11,Сountries!V:Z,5,0) -> 🇪🇹 | U11: =E11=T11 -> TRUE
A12: 11 | B12: America | C12: Central America | D12: Mexico | E12: 🇲🇽 | F12: 131946900 | G12: 0.0083 | H12: 1085893 | I12: 68 | J12: 1943950 | K12: −108,037 | L12: 1.87 | M12: 29.6 | N12: 0.879 | O12: 0.016 | R12: =VLOOKUP(D12,Сountries!V:Z,2,0) -> America | S12: =VLOOKUP(D12,Сountries!V:Z,3,0) -> Central America | T12: =VLOOKUP(D12,Сountries!V:Z,5,0) -> 🇲🇽 | U12: =E12=T12 -> TRUE
A13: 12 | B13: Asia | C13: Eastern Asia | D13: Japan | E13: 🇯🇵 | F13: 123103479 | G13: −0.52% | H13: −649,562 | I13: 338 | J13: 364555 | K13: 140579 | L13: 1.23 | M13: 49.8 | N13: 0.931 | O13: 0.015 | R13: =VLOOKUP(D13,Сountries!V:Z,2,0) -> Asia | S13: =VLOOKUP(D13,Сountries!V:Z,3,0) -> Eastern Asia | T13: =VLOOKUP(D13,Сountries!V:Z,5,0) -> 🇯🇵 | U13: =E13=T13 -> TRUE
A14: 13 | B14: Africa | C14: Northern Africa | D14: Egypt | E14: 🇪🇬 | F14: 118365995 | G14: 0.0157 | H14: 1827737 | I14: 119 | J14: 995450 | K14: −57,305 | L14: 2.71 | M14: 24.5 | N14: 0.409 | O14: 0.0144 | R14: =VLOOKUP(D14,Сountries!V:Z,2,0) -> Africa | S14: =VLOOKUP(D14,Сountries!V:Z,3,0) -> Northern Africa | T14: =VLOOKUP(D14,Сountries!V:Z,5,0) -> 🇪🇬 | U14: =E14=T14 -> TRUE
A15: 14 | B15: Asia | C15: South-Eastern Asia | D15: Philippines | E15: 🇵🇭 | F15: 116786962 | G15: 0.0081 | H15: 943292 | I15: 392 | J15: 298170 | K15: −149,315 | L15: 1.88 | M15: 26.1 | N15: 0.493 | O15: 0.0142 | R15: =VLOOKUP(D15,Сountries!V:Z,2,0) -> Asia | S15: =VLOOKUP(D15,Сountries!V:Z,3,0) -> South-Eastern Asia | T15: =VLOOKUP(D15,Сountries!V:Z,5,0) -> 🇵🇭 | U15: =E15=T15 -> TRUE
A16: 15 | B16: Africa | C16: Middle Africa | D16: DR Congo | E16: 🇨🇩 | F16: 112832473 | G16: 0.0325 | H16: 3556208 | I16: 50 | J16: 2267050 | K16: −27,309 | L16: 5.9 | M16: 15.8 | N16: 0.45 | O16: 0.0137 | R16: =VLOOKUP(D16,Сountries!V:Z,2,0) -> Africa | S16: =VLOOKUP(D16,Сountries!V:Z,3,0) -> Middle Africa | T16: =VLOOKUP(D16,Сountries!V:Z,5,0) -> 🇨🇩 | U16: =E16=T16 -> TRUE
A17: 16 | B17: Asia | C17: South-Eastern Asia | D17: Vietnam | E17: 🇻🇳 | F17: 101598527 | G17: 0.006 | H17: 610841 | I17: 328 | J17: 310070 | K17: −48,171 | L17: 1.88 | M17: 33.4 | N17: 0.414 | O17: 0.0123 | R17: =VLOOKUP(D17,Сountries!V:Z,2,0) -> Asia | S17: =VLOOKUP(D17,Сountries!V:Z,3,0) -> South-Eastern Asia | T17: =VLOOKUP(D17,Сountries!V:Z,5,0) -> 🇻🇳 | U17: =E17=T17 -> TRUE
A18: 17 | B18: Asia | C18: Southern Asia | D18: Iran | E18: 🇮🇷 | F18: 92417681 | G18: 0.0093 | H18: 849943 | I18: 57 | J18: 1628550 | K18: 116786 | L18: 1.67 | M18: 34 | N18: 0.733 | O18: 0.0112 | R18: =VLOOKUP(D18,Сountries!V:Z,2,0) -> Asia | S18: =VLOOKUP(D18,Сountries!V:Z,3,0) -> Southern Asia | T18: =VLOOKUP(D18,Сountries!V:Z,5,0) -> 🇮🇷 | U18: =E18=T18 -> TRUE
A19: 18 | B19: Asia | C19: Western Asia | D19: Turkey | E19: 🇹🇷 | F19: 87685426 | G19: 0.0024 | H19: 211621 | I19: 114 | J19: 769630 | K19: −258,205 | L19: 1.62 | M19: 33.5 | N19: 0.769 | O19: 0.0107 | R19: =VLOOKUP(D19,Сountries!V:Z,2,0) -> Asia | S19: =VLOOKUP(D19,Сountries!V:Z,3,0) -> Western Asia | T19: =VLOOKUP(D19,Сountries!V:Z,5,0) -> 🇹🇷 | U19: =E19=T19 -> TRUE
A20: 19 | B20: Europe | C20: Western Europe | D20: Germany | E20: 🇩🇪 | F20: 84075075 | G20: −0.56% | H20: −477,167 | I20: 241 | J20: 348560 | K20: −334,072 | L20: 1.46 | M20: 45.5 | N20: 0.765 | O20: 0.0102 | R20: =VLOOKUP(D20,Сountries!V:Z,2,0) -> Europe | S20: =VLOOKUP(D20,Сountries!V:Z,3,0) -> Western Europe | T20: =VLOOKUP(D20,Сountries!V:Z,5,0) -> 🇩🇪 | U20: =E20=T20 -> TRUE
A21: 20 | B21: Asia | C21: South-Eastern Asia | D21: Thailand | E21: 🇹🇭 | F21: 71619863 | G21: −0.07% | H21: −48,148 | I21: 140 | J21: 510890 | K21: 27509 | L21: 1.2 | M21: 40.6 | N21: 0.535 | O21: 0.0087 | R21: =VLOOKUP(D21,Сountries!V:Z,2,0) -> Asia | S21: =VLOOKUP(D21,Сountries!V:Z,3,0) -> South-Eastern Asia | T21: =VLOOKUP(D21,Сountries!V:Z,5,0) -> 🇹🇭 | U21: =E21=T21 -> TRUE
A22: 21 | B22: Africa | C22: Eastern Africa | D22: Tanzania | E22: 🇹🇿 | F22: 70545865 | G22: 0.029 | H22: 1985708 | I22: 80 | J22: 885800 | K22: −12,730 | L22: 4.47 | M22: 17.5 | N22: 0.4 | O22: 0.0086 | R22: =VLOOKUP(D22,Сountries!V:Z,2,0) -> Africa | S22: =VLOOKUP(D22,Сountries!V:Z,3,0) -> Eastern Africa | T22: =VLOOKUP(D22,Сountries!V:Z,5,0) -> 🇹🇿 | U22: =E22=T22 -> TRUE
A23: 22 | B23: Europe | C23: Northern Europe | D23: United Kingdom | E23: 🇬🇧 | F23: 69551332 | G23: 0.006 | H23: 413140 | I23: 287 | J23: 241930 | K23: 389911 | L23: 1.54 | M23: 40.1 | N23: 0.845 | O23: 0.0084 | R23: =VLOOKUP(D23,Сountries!V:Z,2,0) -> Europe | S23: =VLOOKUP(D23,Сountries!V:Z,3,0) -> Northern Europe | T23: =VLOOKUP(D23,Сountries!V:Z,5,0) -> 🇬🇧 | U23: =E23=T23 -> TRUE
A24: 23 | B24: Europe | C24: Western Europe | D24: France | E24: 🇫🇷 | F24: 66650804 | G24: 0.0015 | H24: 102274 | I24: 122 | J24: 547557 | K24: 91737 | L24: 1.64 | M24: 42.3 | N24: 0.825 | O24: 0.0081 | R24: =VLOOKUP(D24,Сountries!V:Z,2,0) -> Europe | S24: =VLOOKUP(D24,Сountries!V:Z,3,0) -> Western Europe | T24: =VLOOKUP(D24,Сountries!V:Z,5,0) -> 🇫🇷 | U24: =E24=T24 -> TRUE
A25: 24 | B25: Africa | C25: Southern Africa | D25: South Africa | E25: 🇿🇦 | F25: 64747319 | G25: 0.0116 | H25: 740132 | I25: 53 | J25: 1213090 | K25: 146370 | L25: 2.19 | M25: 28.7 | N25: 0.666 | O25: 0.0079 | R25: =VLOOKUP(D25,Сountries!V:Z,2,0) -> Africa | S25: =VLOOKUP(D25,Сountries!V:Z,3,0) -> Southern Africa | T25: =VLOOKUP(D25,Сountries!V:Z,5,0) -> 🇿🇦 | U25: =E25=T25 -> TRUE
A26: 25 | B26: Europe | C26: Southern Europe | D26: Italy | E26: 🇮🇹 | F26: 59146260 | G26: −0.33% | H26: −196,607 | I26: 201 | J26: 294140 | K26: 75448 | L26: 1.21 | M26: 48.2 | N26: 0.72 | O26: 0.0072 | R26: =VLOOKUP(D26,Сountries!V:Z,2,0) -> Europe | S26: =VLOOKUP(D26,Сountries!V:Z,3,0) -> Southern Europe | T26: =VLOOKUP(D26,Сountries!V:Z,5,0) -> 🇮🇹 | U26: =E26=T26 -> TRUE
A27: 26 | B27: Africa | C27: Eastern Africa | D27: Kenya | E27: 🇰🇪 | F27: 57532493 | G27: 0.0195 | H27: 1099549 | I27: 101 | J27: 569140 | K27: −27,330 | L27: 3.12 | M27: 20 | N27: 0.319 | O27: 0.007 | R27: =VLOOKUP(D27,Сountries!V:Z,2,0) -> Africa | S27: =VLOOKUP(D27,Сountries!V:Z,3,0) -> Eastern Africa | T27: =VLOOKUP(D27,Сountries!V:Z,5,0) -> 🇰🇪 | U27: =E27=T27 -> TRUE
A28: 27 | B28: Asia | C28: South-Eastern Asia | D28: Myanmar | E28: 🇲🇽 | F28: 54850648 | G28: 0.0064 | H28: 350557 | I28: 84 | J28: 653290 | K28: −39,661 | L28: 2.08 | M28: 30.1 | N28: 0.341 | O28: 0.0067 | R28: =VLOOKUP(D28,Сountries!V:Z,2,0) -> Asia | S28: =VLOOKUP(D28,Сountries!V:Z,3,0) -> South-Eastern Asia | T28: =VLOOKUP(D28,Сountries!V:Z,5,0) -> 🇲🇽 | U28: =E28=T28 -> TRUE
A29: 28 | B29: America | C29: South America | D29: Colombia | E29: 🇨🇴 | F29: 53425635 | G29: 0.0102 | H29: 539272 | I29: 48 | J29: 1109500 | K29: 129139 | L29: 1.62 | M29: 32.5 | N29: 0.805 | O29: 0.0065 | R29: =VLOOKUP(D29,Сountries!V:Z,2,0) -> America | S29: =VLOOKUP(D29,Сountries!V:Z,3,0) -> South America | T29: =VLOOKUP(D29,Сountries!V:Z,5,0) -> 🇨🇴 | U29: =E29=T29 -> TRUE
A30: 29 | B30: Asia | C30: Eastern Asia | D30: South Korea | E30: 🇰🇷 | F30: 51667029 | G30: −0.1% | H30: −50,561 | I30: 531 | J30: 97230 | K30: 65731 | L30: 0.75 | M30: 45.6 | N30: 0.824 | O30: 0.0063 | R30: =VLOOKUP(D30,Сountries!V:Z,2,0) -> Asia | S30: =VLOOKUP(D30,Сountries!V:Z,3,0) -> Eastern Asia | T30: =VLOOKUP(D30,Сountries!V:Z,5,0) -> 🇰🇷 | U30: =E30=T30 -> TRUE
A31: 30 | B31: Africa | C31: Northern Africa | D31: Sudan | E31: 🇸🇩 | F31: 51662147 | G31: 0.024 | H31: 1213184 | I31: 29 | J31: 1765048 | K31: 291469 | L31: 4.19 | M31: 18.5 | N31: 0.353 | O31: 0.0063 | R31: =VLOOKUP(D31,Сountries!V:Z,2,0) -> Africa | S31: =VLOOKUP(D31,Сountries!V:Z,3,0) -> Northern Africa | T31: =VLOOKUP(D31,Сountries!V:Z,5,0) -> 🇸🇩 | U31: =E31=T31 -> TRUE
A32: 31 | B32: Africa | C32: Eastern Africa | D32: Uganda | E32: 🇺🇬 | F32: 51384894 | G32: 0.0274 | H32: 1369802 | I32: 257 | J32: 199810 | K32: −119,059 | L32: 4.06 | M32: 16.9 | N32: 0.3 | O32: 0.0062 | R32: =VLOOKUP(D32,Сountries!V:Z,2,0) -> Africa | S32: =VLOOKUP(D32,Сountries!V:Z,3,0) -> Eastern Africa | T32: =VLOOKUP(D32,Сountries!V:Z,5,0) -> 🇺🇬 | U32: =E32=T32 -> TRUE
A33: 32 | B33: Europe | C33: Southern Europe | D33: Spain | E33: 🇪🇸 | F33: 47889958 | G33: −0.04% | H33: −20,568 | I33: 96 | J33: 498800 | K33: 96630 | L33: 1.23 | M33: 45.9 | N33: 0.793 | O33: 0.0058 | R33: =VLOOKUP(D33,Сountries!V:Z,2,0) -> Europe | S33: =VLOOKUP(D33,Сountries!V:Z,3,0) -> Southern Europe | T33: =VLOOKUP(D33,Сountries!V:Z,5,0) -> 🇪🇸 | U33: =E33=T33 -> TRUE
A34: 33 | B34: Africa | C34: Northern Africa | D34: Algeria | E34: 🇩🇿 | F34: 47435312 | G34: 0.0133 | H34: 621004 | I34: 20 | J34: 2381740 | K34: −27,531 | L34: 2.67 | M34: 28.6 | N34: 0.744 | O34: 0.0058 | R34: =VLOOKUP(D34,Сountries!V:Z,2,0) -> Africa | S34: =VLOOKUP(D34,Сountries!V:Z,3,0) -> Northern Africa | T34: =VLOOKUP(D34,Сountries!V:Z,5,0) -> 🇩🇿 | U34: =E34=T34 -> TRUE
A35: 34 | B35: Asia | C35: Western Asia | D35: Iraq | E35: 🇮🇶 | F35: 47020774 | G35: 0.0213 | H35: 978759 | I35: 108 | J35: 434320 | K35: −1,064 | L35: 3.17 | M35: 20.8 | N35: 0.724 | O35: 0.0057 | R35: =VLOOKUP(D35,Сountries!V:Z,2,0) -> Asia | S35: =VLOOKUP(D35,Сountries!V:Z,3,0) -> Western Asia | T35: =VLOOKUP(D35,Сountries!V:Z,5,0) -> 🇮🇶 | U35: =E35=T35 -> TRUE
A36: 35 | B36: America | C36: South America | D36: Argentina | E36: 🇦🇷 | F36: 45851378 | G36: 0.0034 | H36: 155219 | I36: 17 | J36: 2736690 | K36: 2859 | L36: 1.5 | M36: 32.9 | N36: 0.96 | O36: 0.0056 | R36: =VLOOKUP(D36,Сountries!V:Z,2,0) -> America | S36: =VLOOKUP(D36,Сountries!V:Z,3,0) -> South America | T36: =VLOOKUP(D36,Сountries!V:Z,5,0) -> 🇦🇷 | U36: =E36=T36 -> TRUE
A37: 36 | B37: Asia | C37: Southern Asia | D37: Afghanistan | E37: 🇦🇫 | F37: 43844111 | G37: 0.0281 | H37: 1196619 | I37: 67 | J37: 652860 | K37: −74,404 | L37: 4.66 | M37: 17.3 | N37: 0.267 | O37: 0.0053 | R37: =VLOOKUP(D37,Сountries!V:Z,2,0) -> Asia | S37: =VLOOKUP(D37,Сountries!V:Z,3,0) -> Southern Asia | T37: =VLOOKUP(D37,Сountries!V:Z,5,0) -> 🇦🇫 | U37: =E37=T37 -> TRUE
A38: 37 | B38: Asia | C38: Western Asia | D38: Yemen | E38: 🇾🇪 | F38: 41773878 | G38: 0.0293 | H38: 1190714 | I38: 79 | J38: 527970 | K38: −16,291 | L38: 4.41 | M38: 18.4 | N38: 0.33 | O38: 0.0051 | R38: =VLOOKUP(D38,Сountries!V:Z,2,0) -> Asia | S38: =VLOOKUP(D38,Сountries!V:Z,3,0) -> Western Asia | T38: =VLOOKUP(D38,Сountries!V:Z,5,0) -> 🇾🇪 | U38: =E38=T38 -> TRUE
A39: 38 | B39: America | C39: Northern America | D39: Canada | E39: 🇨🇦 | F39: 40126723 | G39: 0.0097 | H39: 384293 | I39: 4 | J39: 9093510 | K39: 326204 | L39: 1.33 | M39: 40.6 | N39: 0.802 | O39: 0.0049 | R39: =VLOOKUP(D39,Сountries!V:Z,2,0) -> America | S39: =VLOOKUP(D39,Сountries!V:Z,3,0) -> Northern America | T39: =VLOOKUP(D39,Сountries!V:Z,5,0) -> 🇨🇦 | U39: =E39=T39 -> TRUE
A40: 39 | B40: Africa | C40: Middle Africa | D40: Angola | E40: 🇦🇴 | F40: 39040039 | G40: 0.0305 | H40: 1154190 | I40: 31 | J40: 1246700 | K40: −3,524 | L40: 4.95 | M40: 16.6 | N40: 0.688 | O40: 0.0047 | R40: =VLOOKUP(D40,Сountries!V:Z,2,0) -> Africa | S40: =VLOOKUP(D40,Сountries!V:Z,3,0) -> Middle Africa | T40: =VLOOKUP(D40,Сountries!V:Z,5,0) -> 🇦🇴 | U40: =E40=T40 -> TRUE
...

Sheet pupulationWorld
A1: # | B1: Country | C1: Population -2025 | D1: World Share | E1: Yearly Change | F1: Net Change | G1: Density (P/Km²) | H1: Land Area (Km²) | I1: Migrants (net) | J1: Fert. Rate | K1: Median Age | L1: Urban Pop %
A2: 1 | B2: India | C2: 1463865525 | D2: 0.1778 | E2: 0.0089 | F2: 12929734 | G2: 492 | H2: 2973190 | I2: −495,753 | J2: 1.94 | K2: 28.8 | L2: 0.371
A3: 2 | B3: China | C3: 1416096094 | D3: 0.172 | E3: −0.23% | F3: −3,225,184 | G3: 151 | H3: 9388211 | I3: −268,126 | J3: 1.02 | K3: 40.1 | L3: 0.675
A4: 3 | B4: United States | C4: 347275807 | D4: 0.0422 | E4: 0.0054 | F4: 1849236 | G4: 38 | H4: 9147420 | I4: 1230663 | J4: 1.62 | K4: 38.5 | L4: 0.828
A5: 4 | B5: Indonesia | C5: 285721236 | D5: 0.0347 | E5: 0.0079 | F5: 2233305 | G5: 158 | H5: 1811570 | I5: −39,509 | J5: 2.1 | K5: 30.4 | L5: 0.596
A6: 5 | B6: Pakistan | C6: 255219554 | D6: 0.031 | E6: 0.0157 | F6: 3950390 | G6: 331 | H6: 770880 | I6: −1,235,336 | J6: 3.5 | K6: 20.6 | L6: 0.344
A7: 6 | B7: Nigeria | C7: 237527782 | D7: 0.0289 | E7: 0.0208 | F7: 4848304 | G7: 261 | H7: 910770 | I7: −15,258 | J7: 4.3 | K7: 18.1 | L7: 0.549
A8: 7 | B8: Brazil | C8: 212812405 | D8: 0.0259 | E8: 0.0038 | F8: 813832 | G8: 25 | H8: 8358140 | I8: −217,283 | J8: 1.6 | K8: 34.8 | L8: 0.914
A9: 8 | B9: Bangladesh | C9: 175686899 | D9: 0.0213 | E9: 0.0122 | F9: 2124535 | G9: 1350 | H9: 130170 | I9: −402,100 | J9: 2.11 | K9: 26 | L9: 0.426
A10: 9 | B10: Russia | C10: 143997393 | D10: 0.0175 | E10: −0.57% | F10: −823,030 | G10: 9 | H10: 16376870 | I10: −251,822 | J10: 1.47 | K10: 40.3 | L10: 0.75
A11: 10 | B11: Ethiopia | C11: 135472051 | D11: 0.0165 | E11: 0.0258 | F11: 3412284 | G11: 135 | H11: 1000000 | I11: 24054 | J11: 3.81 | K11: 19.1 | L11: 0.225
A12: 11 | B12: Mexico | C12: 131946900 | D12: 0.016 | E12: 0.0083 | F12: 1085893 | G12: 68 | H12: 1943950 | I12: −108,037 | J12: 1.87 | K12: 29.6 | L12: 0.879
A13: 12 | B13: Japan | C13: 123103479 | D13: 0.015 | E13: −0.52% | F13: −649,562 | G13: 338 | H13: 364555 | I13: 140579 | J13: 1.23 | K13: 49.8 | L13: 0.931
A14: 13 | B14: Egypt | C14: 118365995 | D14: 0.0144 | E14: 0.0157 | F14: 1827737 | G14: 119 | H14: 995450 | I14: −57,305 | J14: 2.71 | K14: 24.5 | L14: 0.409
A15: 14 | B15: Philippines | C15: 116786962 | D15: 0.0142 | E15: 0.0081 | F15: 943292 | G15: 392 | H15: 298170 | I15: −149,315 | J15: 1.88 | K15: 26.1 | L15: 0.493
A16: 15 | B16: DR Congo | C16: 112832473 | D16: 0.0137 | E16: 0.0325 | F16: 3556208 | G16: 50 | H16: 2267050 | I16: −27,309 | J16: 5.9 | K16: 15.8 | L16: 0.45
A17: 16 | B17: Vietnam | C17: 101598527 | D17: 0.0123 | E17: 0.006 | F17: 610841 | G17: 328 | H17: 310070 | I17: −48,171 | J17: 1.88 | K17: 33.4 | L17: 0.414
A18: 17 | B18: Iran | C18: 92417681 | D18: 0.0112 | E18: 0.0093 | F18: 849943 | G18: 57 | H18: 1628550 | I18: 116786 | J18: 1.67 | K18: 34 | L18: 0.733
A19: 18 | B19: Turkey | C19: 87685426 | D19: 0.0107 | E19: 0.0024 | F19: 211621 | G19: 114 | H19: 769630 | I19: −258,205 | J19: 1.62 | K19: 33.5 | L19: 0.769
A20: 19 | B20: Germany | C20: 84075075 | D20: 0.0102 | E20: −0.56% | F20: −477,167 | G20: 241 | H20: 348560 | I20: −334,072 | J20: 1.46 | K20: 45.5 | L20: 0.765
A21: 20 | B21: Thailand | C21: 71619863 | D21: 0.0087 | E21: −0.07% | F21: −48,148 | G21: 140 | H21: 510890 | I21: 27509 | J21: 1.2 | K21: 40.6 | L21: 0.535
A22: 21 | B22: Tanzania | C22: 70545865 | D22: 0.0086 | E22: 0.029 | F22: 1985708 | G22: 80 | H22: 885800 | I22: −12,730 | J22: 4.47 | K22: 17.5 | L22: 0.4
A23: 22 | B23: United Kingdom | C23: 69551332 | D23: 0.0084 | E23: 0.006 | F23: 413140 | G23: 287 | H23: 241930 | I23: 389911 | J23: 1.54 | K23: 40.1 | L23: 0.845
A24: 23 | B24: France | C24: 66650804 | D24: 0.0081 | E24: 0.0015 | F24: 102274 | G24: 122 | H24: 547557 | I24: 91737 | J24: 1.64 | K24: 42.3 | L24: 0.825
A25: 24 | B25: South Africa | C25: 64747319 | D25: 0.0079 | E25: 0.0116 | F25: 740132 | G25: 53 | H25: 1213090 | I25: 146370 | J25: 2.19 | K25: 28.7 | L25: 0.666
A26: 25 | B26: Italy | C26: 59146260 | D26: 0.0072 | E26: −0.33% | F26: −196,607 | G26: 201 | H26: 294140 | I26: 75448 | J26: 1.21 | K26: 48.2 | L26: 0.72
A27: 26 | B27: Kenya | C27: 57532493 | D27: 0.007 | E27: 0.0195 | F27: 1099549 | G27: 101 | H27: 569140 | I27: −27,330 | J27: 3.12 | K27: 20 | L27: 0.319
A28: 27 | B28: Myanmar | C28: 54850648 | D28: 0.0067 | E28: 0.0064 | F28: 350557 | G28: 84 | H28: 653290 | I28: −39,661 | J28: 2.08 | K28: 30.1 | L28: 0.341
A29: 28 | B29: Colombia | C29: 53425635 | D29: 0.0065 | E29: 0.0102 | F29: 539272 | G29: 48 | H29: 1109500 | I29: 129139 | J29: 1.62 | K29: 32.5 | L29: 0.805
A30: 29 | B30: South Korea | C30: 51667029 | D30: 0.0063 | E30: −0.1% | F30: −50,561 | G30: 531 | H30: 97230 | I30: 65731 | J30: 0.75 | K30: 45.6 | L30: 0.824
A31: 30 | B31: Sudan | C31: 51662147 | D31: 0.0063 | E31: 0.024 | F31: 1213184 | G31: 29 | H31: 1765048 | I31: 291469 | J31: 4.19 | K31: 18.5 | L31: 0.353
A32: 31 | B32: Uganda | C32: 51384894 | D32: 0.0062 | E32: 0.0274 | F32: 1369802 | G32: 257 | H32: 199810 | I32: −119,059 | J32: 4.06 | K32: 16.9 | L32: 0.3
A33: 32 | B33: Spain | C33: 47889958 | D33: 0.0058 | E33: −0.04% | F33: −20,568 | G33: 96 | H33: 498800 | I33: 96630 | J33: 1.23 | K33: 45.9 | L33: 0.793
A34: 33 | B34: Algeria | C34: 47435312 | D34: 0.0058 | E34: 0.0133 | F34: 621004 | G34: 20 | H34: 2381740 | I34: −27,531 | J34: 2.67 | K34: 28.6 | L34: 0.744
A35: 34 | B35: Iraq | C35: 47020774 | D35: 0.0057 | E35: 0.0213 | F35: 978759 | G35: 108 | H35: 434320 | I35: −1,064 | J35: 3.17 | K35: 20.8 | L35: 0.724
A36: 35 | B36: Argentina | C36: 45851378 | D36: 0.0056 | E36: 0.0034 | F36: 155219 | G36: 17 | H36: 2736690 | I36: 2859 | J36: 1.5 | K36: 32.9 | L36: 0.96
A37: 36 | B37: Afghanistan | C37: 43844111 | D37: 0.0053 | E37: 0.0281 | F37: 1196619 | G37: 67 | H37: 652860 | I37: −74,404 | J37: 4.66 | K37: 17.3 | L37: 0.267
A38: 37 | B38: Yemen | C38: 41773878 | D38: 0.0051 | E38: 0.0293 | F38: 1190714 | G38: 79 | H38: 527970 | I38: −16,291 | J38: 4.41 | K38: 18.4 | L38: 0.33
A39: 38 | B39: Canada | C39: 40126723 | D39: 0.0049 | E39: 0.0097 | F39: 384293 | G39: 4 | H39: 9093510 | I39: 326204 | J39: 1.33 | K39: 40.6 | L39: 0.802
A40: 39 | B40: Angola | C40: 39040039 | D40: 0.0047 | E40: 0.0305 | F40: 1154190 | G40: 31 | H40: 1246700 | I40: −3,524 | J40: 4.95 | K40: 16.6 | L40: 0.688
...

Sheet Area
A1: # | B1: region | C1: flag | D1: Country | E1: Tot. Area (Km²) | F1: Tot. Area (mi²) | G1: Land Area (Km²) | H1: Land Area (mi²) | I1: World Share | L1: region | M1: flag
A2: 1 | B2: Europe | C2: 🇷🇺 | D2: Russian Federation | E2: 17098242 | F2: 6601665 | G2: 16376870 | H2: 6323142 | I2: 0.11 | L2: =VLOOKUP(D2,Сountries!V:Z,2,0) -> Europe | M2: =VLOOKUP(D2,Сountries!V:Z,5,0) -> 🇷🇺
A3: 2 | B3: America | C3: 🇨🇦 | D3: Canada | E3: 9984670 | F3: 3855101 | G3: 9093510 | H3: 3511022 | I3: 0.0611 | L3: =VLOOKUP(D3,Сountries!V:Z,2,0) -> America | M3: =VLOOKUP(D3,Сountries!V:Z,5,0) -> 🇨🇦
A4: 3 | B4: Asia | C4: 🇨🇳 | D4: China | E4: 9706961 | F4: 3747877 | G4: 9388211 | H4: 3624807 | I4: 0.063 | L4: =VLOOKUP(D4,Сountries!V:Z,2,0) -> Asia | M4: =VLOOKUP(D4,Сountries!V:Z,5,0) -> 🇨🇳
A5: 4 | B5: America | C5: 🇺🇸 | D5: United States | E5: 9372610 | F5: 3618783 | G5: 9147420 | H5: 3531837 | I5: 0.0614 | L5: =VLOOKUP(D5,Сountries!V:Z,2,0) -> America | M5: =VLOOKUP(D5,Сountries!V:Z,5,0) -> 🇺🇸
A6: 5 | B6: America | C6: 🇧🇷 | D6: Brazil | E6: 8515767 | F6: 3287955 | G6: 8358140 | H6: 3227095 | I6: 0.0561 | L6: =VLOOKUP(D6,Сountries!V:Z,2,0) -> America | M6: =VLOOKUP(D6,Сountries!V:Z,5,0) -> 🇧🇷
A7: 6 | B7: Australia and New Zealand | C7: 🇦🇺 | D7: Australia | E7: 7692024 | F7: 2969906 | G7: 7682300 | H7: 2966151 | I7: 0.0516 | L7: =VLOOKUP(D7,Сountries!V:Z,2,0) -> Australia and New Zealand | M7: =VLOOKUP(D7,Сountries!V:Z,5,0) -> 🇦🇺
A8: 7 | B8: Asia | C8: 🇮🇳 | D8: India | E8: 3287590 | F8: 1269345 | G8: 2973190 | H8: 1147955 | I8: 0.02 | L8: =VLOOKUP(D8,Сountries!V:Z,2,0) -> Asia | M8: =VLOOKUP(D8,Сountries!V:Z,5,0) -> 🇮🇳
A9: 8 | B9: America | C9: 🇦🇷 | D9: Argentina | E9: 2780400 | F9: 1073518 | G9: 2736690 | H9: 1056641 | I9: 0.0184 | L9: =VLOOKUP(D9,Сountries!V:Z,2,0) -> America | M9: =VLOOKUP(D9,Сountries!V:Z,5,0) -> 🇦🇷
A10: 9 | B10: Asia | C10: 🇰🇿 | D10: Kazakhstan | E10: 2724900 | F10: 1052089 | G10: 2699700 | H10: 1042360 | I10: 0.0181 | L10: =VLOOKUP(D10,Сountries!V:Z,2,0) -> Asia | M10: =VLOOKUP(D10,Сountries!V:Z,5,0) -> 🇰🇿
A11: 10 | B11: Africa | C11: 🇩🇿 | D11: Algeria | E11: 2381741 | F11: 919595 | G11: 2381740 | H11: 919595 | I11: 0.016 | L11: =VLOOKUP(D11,Сountries!V:Z,2,0) -> Africa | M11: =VLOOKUP(D11,Сountries!V:Z,5,0) -> 🇩🇿
A12: 11 | B12: Africa | C12: 🇨🇩 | D12: DR Congo | E12: 2344858 | F12: 905354 | G12: 2267050 | H12: 875313 | I12: 0.0152 | L12: =VLOOKUP(D12,Сountries!V:Z,2,0) -> Africa | M12: =VLOOKUP(D12,Сountries!V:Z,5,0) -> 🇨🇩
A13: 12 | B13: America | C13: 🇬🇱 | D13: Greenland | E13: 2166086 | F13: 836330 | G13: 410450 | H13: 158476 | I13: 0.0028 | L13: =VLOOKUP(D13,Сountries!V:Z,2,0) -> America | M13: =VLOOKUP(D13,Сountries!V:Z,5,0) -> 🇬🇱
... A234: 233 | B234: Europe | C234: 🇻🇦 | D234: Holy See | E234: 0 | F234: 0 | G234: 0 | H234: 0 | I234: 2.7e-09 | L234: =VLOOKUP(D234,Сountries!V:Z,2,0) -> Europe | M234: =VLOOKUP(D234,Сountries!V:Z,5,0) -> 🇻🇦

Sheet GDPByCountry
A1: # | B1: region | C1: Flags | D1: Country | E1: Flags | F1: region | G1: GDP (nominal, 2023) | H1: GDP (calc billion) | I1: GDP (abbrev.) | J1: GDP Growth | K1: Population 2023 | L1: GDP per capita | M1: Share of World GDP
A2: 1 | B2: America | C2: 🇺🇸 | D2: United States | E2: =VLOOKUP(D2,all_countries!D:E,2,0) -> 🇺🇸 | F2: =VLOOKUP(D2,Сountries!V:Z,2,0) -> America | G2: 27720700000000 | H2: =G2/1000000000 -> 27720.7 | I2: 27.721 trillion | J2: 0.0289 | K2: 343477335 | L2: 80706 | M2: 0.2611
A3: 2 | B3: Asia | C3: 🇨🇳 | D3: China | E3: =VLOOKUP(D3,all_countries!D:E,2,0) -> 🇨🇳 | F3: =VLOOKUP(D3,Сountries!V:Z,2,0) -> Asia | G3: 17794800000000 | H3: =G3/1000000000 -> 17794.8 | I3: 17.795 trillion | J3: 0.0525 | K3: 1422584933 | L3: 12509 | M3: 0.1676
A4: 3 | B4: Europe | C4: 🇩🇪 | D4: Germany | E4: =VLOOKUP(D4,all_countries!D:E,2,0) -> 🇩🇪 | F4: =VLOOKUP(D4,Сountries!V:Z,2,0) -> Europe | G4: 4525700000000 | H4: =G4/1000000000 -> 4525.7 | I4: 4.526 trillion | J4: −0.27% | K4: 84548231 | L4: 53528 | M4: 0.0426
A5: 4 | B5: Asia | C5: 🇯🇵 | D5: Japan | E5: =VLOOKUP(D5,all_countries!D:E,2,0) -> 🇯🇵 | F5: =VLOOKUP(D5,Сountries!V:Z,2,0) -> Asia | G5: 4204490000000 | H5: =G5/1000000000 -> 4204.49 | I5: 4.204 trillion | J5: 0.0168 | K5: 124370947 | L5: 33806 | M5: 0.0396
A6: 5 | B6: Asia | C6: 🇮🇳 | D6: India | E6: =VLOOKUP(D6,all_countries!D:E,2,0) -> 🇮🇳 | F6: =VLOOKUP(D6,Сountries!V:Z,2,0) -> Asia | G6: 3567550000000 | H6: =G6/1000000000 -> 3567.55 | I6: 3.568 trillion | J6: 0.0815 | K6: 1438069596 | L6: 2481 | M6: 0.0336
A7: 6 | B7: Europe | C7: 🇬🇧 | D7: United Kingdom | E7: =VLOOKUP(D7,all_countries!D:E,2,0) -> 🇬🇧 | F7: =VLOOKUP(D7,Сountries!V:Z,2,0) -> Europe | G7: 3380850000000 | H7: =G7/1000000000 -> 3380.85 | I7: 3.381 trillion | J7: 0.0034 | K7: 68682962 | L7: 49224 | M7: 0.0318
A8: 7 | B8: Europe | C8: 🇫🇷 | D8: France | E8: =VLOOKUP(D8,all_countries!D:E,2,0) -> 🇫🇷 | F8: =VLOOKUP(D8,Сountries!V:Z,2,0) -> Europe | G8: 3051830000000 | H8: =G8/1000000000 -> 3051.83 | I8: 3.052 trillion | J8: 0.0094 | K8: 66438822 | L8: 45934 | M8: 0.0287
A9: 8 | B9: Europe | C9: 🇮🇹 | D9: Italy | E9: =VLOOKUP(D9,all_countries!D:E,2,0) -> 🇮🇹 | F9: =VLOOKUP(D9,Сountries!V:Z,2,0) -> Europe | G9: 2300940000000 | H9: =G9/1000000000 -> 2300.94 | I9: 2.301 trillion | J9: 0.007 | K9: 59499453 | L9: 38672 | M9: 0.0217
A10: 9 | B10: America | C10: 🇧🇷 | D10: Brazil | E10: =VLOOKUP(D10,all_countries!D:E,2,0) -> 🇧🇷 | F10: =VLOOKUP(D10,Сountries!V:Z,2,0) -> America | G10: 2173670000000 | H10: =G10/1000000000 -> 2173.67 | I10: 2.174 trillion | J10: 0.0291 | K10: 211140729 | L10: 10295 | M10: 0.0205
A11: 10 | B11: America | C11: 🇨🇦 | D11: Canada | E11: =VLOOKUP(D11,all_countries!D:E,2,0) -> 🇨🇦 | F11: =VLOOKUP(D11,Сountries!V:Z,2,0) -> America | G11: 2142470000000 | H11: =G11/1000000000 -> 2142.47 | I11: 2.142 trillion | J11: 0.0125 | K11: 39299105 | L11: 54517 | M11: 0.0202
A12: 11 | B12: Europe | C12: 🇷🇺 | D12: Russian Federation | E12: =VLOOKUP(D12,all_countries!D:E,2,0) -> 🇷🇺 | F12: =VLOOKUP(D12,Сountries!V:Z,2,0) -> Europe | G12: 2021420000000 | H12: =G12/1000000000 -> 2021.42 | I12: 2.021 trillion | J12: 0.036 | K12: 145440500 | L12: 13899 | M12: 0.019
A13: 12 | B13: America | C13: 🇲🇽 | D13: Mexico | E13: =VLOOKUP(D13,all_countries!D:E,2,0) -> 🇲🇽 | F13: =VLOOKUP(D13,Сountries!V:Z,2,0) -> America | G13: 1789110000000 | H13: =G13/1000000000 -> 1789.11 | I13: 1.789 trillion | J13: 0.032 | K13: 129739759 | L13: 13790 | M13: 0.0169
A14: 13 | B14: Australia and New Zealand | C14: 🇦🇺 | D14: Australia | E14: =VLOOKUP(D14,all_countries!D:E,2,0) -> 🇦🇺 | F14: =VLOOKUP(D14,Сountries!V:Z,2,0) -> Australia and New Zealand | G14: 1728060000000 | H14: =G14/1000000000 -> 1728.06 | I14: 1.728 trillion | J14: 0.0344 | K14: 26451124 | L14: 65330 | M14: 0.0163
A15: 14 | B15: Asia | C15: 🇰🇷 | D15: South Korea | E15: =VLOOKUP(D15,all_countries!D:E,2,0) -> 🇰🇷 | F15: =VLOOKUP(D15,Сountries!V:Z,2,0) -> Asia | G15: 1712790000000 | H15: =G15/1000000000 -> 1712.79 | I15: 1.713 trillion | J15: 0.0136 | K15: 51748739 | L15: 33098 | M15: 0.0161
A16: 15 | B16: Europe | C16: 🇪🇸 | D16: Spain | E16: =VLOOKUP(D16,all_countries!D:E,2,0) -> 🇪🇸 | F16: =VLOOKUP(D16,Сountries!V:Z,2,0) -> Europe | G16: 1620090000000 | H16: =G16/1000000000 -> 1620.09 | I16: 1.62 trillion | J16: 0.0268 | K16: 47911579 | L16: 33814 | M16: 0.0153
... A19: 18 | B19: Asia | C19: 🇹🇷 | D19: Turkey | E19: =VLOOKUP(D19,all_countries!D:E,2,0) -> 🇹🇷 | F19: =VLOOKUP(D19,Сountries!V:Z,2,0) -> Asia | G19: 1118250000000 | H19: =G19/1000000000 -> 1118.25 | I19: 1.118 trillion | J19: 0.0511 | K19: 87270501 | L19: 12814 | M19: 0.0105
A20: 19 | B20: Asia | C20: 🇸🇦 | D20: Saudi Arabia | E20: =VLOOKUP(D20,all_countries!D:E,2,0) -> 🇸🇦 | F20: =VLOOKUP(D20,Сountries!V:Z,2,0) -> Asia | G20: 1067580000000 | H20: =G20/1000000000 -> 1067.58 | I20: 1.068 trillion | J20: −0.76% | K20: 33264292 | L20: 32094 | M20: 0.0101
A21: 20 | B21: Europe | C21: 🇨🇭 | D21: Switzerland | E21: =VLOOKUP(D21,all_countries!D:E,2,0) -> 🇨🇭 | F21: =VLOOKUP(D21,Сountries!V:Z,2,0) -> Europe | G21: 884940000000 | H21: =G21/1000000000 -> 884.94 | I21: 884.94 billion | J21: 0.0072 | K21: 8870561 | L21: 99761 | M21: 0.0083
A22: 21 | B22: Europe | C22: 🇵🇱 | D22: Poland | E22: =VLOOKUP(D22,all_countries!D:E,2,0) -> 🇵🇱 | F22: =VLOOKUP(D22,Сountries!V:Z,2,0) -> Europe | G22: 809201000000 | H22: =G22/1000000000 -> 809.201 | I22: 809.201 billion | J22: 0.0014 | K22: 38762844 | L22: 20876 | M22: 0.0076
A23: 22 | B23: America | C23: 🇦🇷 | D23: Argentina | E23: =VLOOKUP(D23,all_countries!D:E,2,0) -> 🇦🇷 | F23: =VLOOKUP(D23,Сountries!V:Z,2,0) -> America | G23: 646075000000 | H23: =G23/1000000000 -> 646.075 | I23: 646.075 billion | J23: −1.61% | K23: 45538401 | L23: 14187 | M23: 0.0061
A24: 23 | B24: Europe | C24: 🇧🇪 | D24: Belgium | E24: =VLOOKUP(D24,all_countries!D:E,2,0) -> 🇧🇪 | F24: =VLOOKUP(D24,Сountries!V:Z,2,0) -> Europe | G24: 644783000000 | H24: =G24/1000000000 -> 644.783 | I24: 644.783 billion | J24: 0.0125 | K24: 11712893 | L24: 55049 | M24: 0.0061
A25: 24 | B25: Europe | C25: 🇸🇪 | D25: Sweden | E25: =VLOOKUP(D25,all_countries!D:E,2,0) -> 🇸🇪 | F25: =VLOOKUP(D25,Сountries!V:Z,2,0) -> Europe | G25: 584960000000 | H25: =G25/1000000000 -> 584.96 | I25: 584.96 billion | J25: −0.31% | K25: 10551494 | L25: 55439 | M25: 0.0055
A26: 25 | B26: Europe | C26: 🇮🇪 | D26: Ireland | E26: =VLOOKUP(D26,all_countries!D:E,2,0) -> 🇮🇪 | F26: =VLOOKUP(D26,Сountries!V:Z,2,0) -> Europe | G26: 551395000000 | H26: =G26/1000000000 -> 551.395 | I26: 551.395 billion | J26: −5.53% | K26: 5196630 | L26: 106106 | M26: 0.0052
A27: 26 | B27: Asia | C27: 🇹🇭 | D27: Thailand | E27: =VLOOKUP(D27,all_countries!D:E,2,0) -> 🇹🇭 | F27: =VLOOKUP(D27,Сountries!V:Z,2,0) -> Asia | G27: 514969000000 | H27: =G27/1000000000 -> 514.969 | I27: 514.969 billion | J27: 0.0189 | K27: 71702435 | L27: 7182 | M27: 0.0049
A28: 27 | B28: Asia | C28: 🇦🇪 | D28: United Arab Emirates | E28: =VLOOKUP(D28,all_countries!D:E,2,0) -> 🇦🇪 | F28: =VLOOKUP(D28,Сountries!V:Z,2,0) -> Asia | G28: 514130000000 | H28: =G28/1000000000 -> 514.13 | I28: 514.13 billion | J28: 0.0362 | K28: 10642081 | L28: 48311 | M28: 0.0048
A29: 28 | B29: Asia | C29: 🇮🇱 | D29: Israel | E29: =VLOOKUP(D29,all_countries!D:E,2,0) -> 🇮🇱 | F29: =VLOOKUP(D29,Сountries!V:Z,2,0) -> Asia | G29: 513611000000 | H29: =G29/1000000000 -> 513.611 | I29: 513.611 billion | J29: 0.0242 | K29: 9256314 | L29: 55488 | M29: 0.0048
A30: 29 | B30: Europe | C30: 🇦🇹 | D30: Austria | E30: =VLOOKUP(D30,all_countries!D:E,2,0) -> 🇦🇹 | F30: =VLOOKUP(D30,Сountries!V:Z,2,0) -> Europe | G30: 511685000000 | H30: =G30/1000000000 -> 511.685 | I30: 511.685 billion | J30: −0.95% | K30: 9130429 | L30: 56042 | M30: 0.0048
A31: 30 | B31: Asia | C31: 🇸🇬 | D31: Singapore | E31: =VLOOKUP(D31,all_countries!D:E,2,0) -> 🇸🇬 | F31: =VLOOKUP(D31,Сountries!V:Z,2,0) -> Asia | G31: 501428000000 | H31: =G31/1000000000 -> 501.428 | I31: 501.428 billion | J31: 0.0107 | K31: 5789090 | L31: 86616 | M31: 0.0047
A32: 31 | B32: Europe | C32: 🇳🇴 | D32: Norway | E32: =VLOOKUP(D32,all_countries!D:E,2,0) -> 🇳🇴 | F32: =VLOOKUP(D32,Сountries!V:Z,2,0) -> Europe | G32: 485311000000 | H32: =G32/1000000000 -> 485.311 | I32: 485.311 billion | J32: 0.0048 | K32: 5519167 | L32: 87932 | M32: 0.0046
A33: 32 | B33: Asia | C33: 🇧🇩 | D33: Bangladesh | E33: =VLOOKUP(D33,all_countries!D:E,2,0) -> 🇧🇩 | F33: =VLOOKUP(D33,Сountries!V:Z,2,0) -> Asia | G33: 437415000000 | H33: =G33/1000000000 -> 437.415 | I33: 437.415 billion | J33: 0.0578 | K33: 171466990 | L33: 2551 | M33: 0.0041
A34: 33 | B34: Asia | C34: 🇵🇭 | D34: Philippines | E34: =VLOOKUP(D34,all_countries!D:E,2,0) -> 🇵🇭 | F34: =VLOOKUP(D34,Сountries!V:Z,2,0) -> Asia | G34: 437146000000 | H34: =G34/1000000000 -> 437.146 | I34: 437.146 billion | J34: 0.0555 | K34: 114891199 | L34: 3805 | M34: 0.0041
A35: 34 | B35: Asia | C35: 🇻🇳 | D35: Vietnam | E35: =VLOOKUP(D35,all_countries!D:E,2,0) -> 🇻🇳 | F35: =VLOOKUP(D35,Сountries!V:Z,2,0) -> Asia | G35: 429717000000 | H35: =G35/1000000000 -> 429.717 | I35: 429.717 billion | J35: 0.0505 | K35: 100352192 | L35: 4282 | M35: 0.004
A36: 35 | B36: Europe | C36: 🇩🇰 | D36: Denmark | E36: =VLOOKUP(D36,all_countries!D:E,2,0) -> 🇩🇰 | F36: =VLOOKUP(D36,Сountries!V:Z,2,0) -> Europe | G36: 407092000000 | H36: =G36/1000000000 -> 407.092 | I36: 407.092 billion | J36: 0.025 | K36: 5948136 | L36: 68440 | M36: 0.0038
A37: 36 | B37: Asia | C37: 🇮🇷 | D37: Iran | E37: =VLOOKUP(D37,all_countries!D:E,2,0) -> 🇮🇷 | F37: =VLOOKUP(D37,Сountries!V:Z,2,0) -> Asia | G37: 404626000000 | H37: =G37/1000000000 -> 404.626 | I37: 404.626 billion | J37: 0.0504 | K37: 90608707 | L37: 4466 | M37: 0.0038
A38: 37 | B38: Asia | C38: 🇲🇾 | D38: Malaysia | E38: =VLOOKUP(D38,all_countries!D:E,2,0) -> 🇲🇾 | F38: =VLOOKUP(D38,Сountries!V:Z,2,0) -> Asia | G38: 399705000000 | H38: =G38/1000000000 -> 399.705 | I38: 399.705 billion | J38: 0.0356 | K38: 35126298 | L38: 11379 | M38: 0.0038
A39: 38 | B39: Africa | C39: 🇪🇬 | D39: Egypt | E39: =VLOOKUP(D39,all_countries!D:E,2,0) -> 🇪🇬 | F39: =VLOOKUP(D39,Сountries!V:Z,2,0) -> Africa | G39: 396002000000 | H39: =G39/1000000000 -> 396.002 | I39: 396.002 billion | J39: 0.0376 | K39: 114535772 | L39: 3457 | M39: 0.0037
A40: 39 | B40: Asia | C40: 🇭🇰 | D40: Hong Kong | E40: =VLOOKUP(D40,all_countries!D:E,2,0) -> 🇭🇰 | F40: =VLOOKUP(D40,Сountries!V:Z,2,0) -> Asia | G40: 380812000000 | H40: =G40/1000000000 -> 380.812 | I40: 380.812 billion | J40: 0.0328 | K40: 7442734 | L40: 51166 | M40: 0.0036
A41: 40 | B41: Africa | C41: 🇿🇦 | D41: South Africa | E41: =VLOOKUP(D41,all_countries!D:E,2,0) -> 🇿🇦 | F41: =VLOOKUP(D41,Сountries!V:Z,2,0) -> Africa | G41: 380699000000 | H41: =G41/1000000000 -> 380.699 | I41: 380.699 billion | J41: 0.007 | K41: 63212384 | L41: 6023 | M41: 0.0036
A42: 41 | B42: Africa | C42: 🇳🇬 | D42: Nigeria | E42: =VLOOKUP(D42,all_countries!D:E,2,0) -> 🇳🇬 | F42: =VLOOKUP(D42,Сountries!V:Z,2,0) -> Africa | G42: 363846000000 | H42: =G42/1000000000 -> 363.846 | I42: 363.846 billion | J42: 0.0286 | K42: 227882945 | L42: 1597 | M42: 0.0034
...

Sheet GDPPerCapita
A1: # | B1: region | C1: flags | D1: country | E1: Flags | F1: region | G1: GDP (PPP) per capita 2023 | H1: GDP (nominal) per capita 2023 | I1: vs World PPP GDP per capita $22,837
A2: 1 | B2: Asia | C2: 🇸🇬 | D2: Singapore | E2: =VLOOKUP(D2,all_countries!D:E,2,0) -> 🇸🇬 | F2: =VLOOKUP(D2,Сountries!V:Z,2,0) -> Asia | G2: 141553 | H2: 86616 | I2: 6.2
A3: 2 | B3: Europe | C3: 🇱🇺 | D3: Luxembourg | E3: =VLOOKUP(D3,all_countries!D:E,2,0) -> 🇱🇺 | F3: =VLOOKUP(D3,Сountries!V:Z,2,0) -> Europe | G3: 139106 | H3: 128936 | I3: 6.09
A4: 3 | B4: Asia | C4: 🇶🇦 | D4: Qatar | E4: =VLOOKUP(D4,all_countries!D:E,2,0) -> 🇶🇦 | F4: =VLOOKUP(D4,Сountries!V:Z,2,0) -> Asia | G4: 128919 | H4: 71500 | I4: 5.65
A5: 4 | B5: Europe | C5: 🇮🇪 | D5: Ireland | E5: =VLOOKUP(D5,all_countries!D:E,2,0) -> 🇮🇪 | F5: =VLOOKUP(D5,Сountries!V:Z,2,0) -> Europe | G5: 124578 | H5: 106106 | I5: 5.46
A6: 5 | B6: Asia | C6: 🇲🇴 | D6: Macao | E6: =VLOOKUP(D6,all_countries!D:E,2,0) -> 🇲🇴 | F6: =VLOOKUP(D6,Сountries!V:Z,2,0) -> Asia | G6: 116491 | H6: 64158 | I6: 5.1
A7: 6 | B7: Europe | C7: 🇳🇴 | D7: Norway | E7: =VLOOKUP(D7,all_countries!D:E,2,0) -> 🇳🇴 | F7: =VLOOKUP(D7,Сountries!V:Z,2,0) -> Europe | G7: 100668 | H7: 87932 | I7: 4.41
A8: 7 | B8: Europe | C8: 🇨🇭 | D8: Switzerland | E8: =VLOOKUP(D8,all_countries!D:E,2,0) -> 🇨🇭 | F8: =VLOOKUP(D8,Сountries!V:Z,2,0) -> Europe | G8: 89315 | H8: 99761 | I8: 3.91
A9: 8 | B9: Oceania | C9: 🇧🇳 | D9: Brunei | E9: =VLOOKUP(D9,all_countries!D:E,2,0) -> 🇧🇳 | F9: =VLOOKUP(D9,Сountries!V:Z,2,0) -> Oceania | G9: 85268 | H9: 32963 | I9: 3.73
A10: 9 | B10: America | C10: 🇺🇸 | D10: United States | E10: =VLOOKUP(D10,all_countries!D:E,2,0) -> 🇺🇸 | F10: =VLOOKUP(D10,Сountries!V:Z,2,0) -> America | G10: 82769 | H10: 80706 | I10: 3.62
A11: 10 | B11: Europe | C11: 🇳🇱 | D11: Netherlands | E11: =VLOOKUP(D11,all_countries!D:E,2,0) -> 🇳🇱 | F11: =VLOOKUP(D11,Сountries!V:Z,2,0) -> Europe | G11: 78103 | H11: 63803 | I11: 3.42
A12: 11 | B12: Europe | C12: 🇮🇸 | D12: Iceland | E12: =VLOOKUP(D12,all_countries!D:E,2,0) -> 🇮🇸 | F12: =VLOOKUP(D12,Сountries!V:Z,2,0) -> Europe | G12: 76159 | H12: 80827 | I12: 3.33
A13: 12 | B13: Asia | C13: 🇦🇪 | D13: United Arab Emirates | E13: =VLOOKUP(D13,all_countries!D:E,2,0) -> 🇦🇪 | F13: =VLOOKUP(D13,Сountries!V:Z,2,0) -> Asia | G13: 76110 | H13: 48311 | I13: 3.33
... A182: 181 | B182: Africa | C182: 🇧🇮 | D182: Burundi | E182: =VLOOKUP(D182,all_countries!D:E,2,0) -> 🇧🇮 | F182: =VLOOKUP(D182,Сountries!V:Z,2,0) -> Africa | G182: 920 | H182: 193 | I182: 0.04

Sheet BirthsPerDay
A1: # | B1: Region detail | C1: Region | D1: Flags | E1: Country | F1: Number of Births Per Day
A2: 1 | B2: Southern Asia | C2: Asia | D2: 🇮🇳 | E2: India | F2: 63171
A3: 2 | B3: Eastern Asia | C3: Asia | D3: 🇨🇳 | E3: China | F3: 23845
A4: 3 | B4: Western Africa | C4: Africa | D4: 🇳🇬 | E4: Nigeria | F4: 20919
A5: 4 | B5: Southern Asia | C5: Asia | D5: 🇵🇰 | E5: Pakistan | F5: 18917
A6: 5 | B6: Middle Africa | C6: Africa | D6: 🇨🇩 | E6: DR Congo | F6: 12484
A7: 6 | B7: South-Eastern Asia | C7: Asia | D7: 🇮🇩 | E7: Indonesia | F7: 12158
A8: 7 | B8: Eastern Africa | C8: Africa | D8: 🇪🇹 | E8: Ethiopia | F8: 11435
A9: 8 | B9: Northern America | C9: Northern America | D9: 🇺🇸 | E9: United States | F9: 10031
A10: 9 | B10: Southern Asia | C10: Asia | D10: 🇧🇩 | E10: Bangladesh | F10: 9422
A11: 10 | B11: South America | C11: South America | D11: 🇧🇷 | E11: Brazil | F11: 6923
A12: 11 | B12: Northern Africa | C12: Africa | D12: 🇪🇬 | E12: Egypt | F12: 6708
A13: 12 | B13: Eastern Africa | C13: Africa | D13: 🇹🇿 | E13: Tanzania | F13: 6624
... A101: 100 | B101: Central America | C101: South America | D101: 🇳🇮 | E101: Nicaragua | F101: 362

Sheet GPI-162
A1: # | B1: Region | C1: Flag | D1: Country | E1: GPI 2024 | H1: Region | I1: Flag
A2: 1 | B2: Europe | C2: 🇮🇸 | D2: Iceland | E2: 1.112 | H2: =VLOOKUP(D2,Сountries!V:Z,2,0) -> Europe | I2: =VLOOKUP(D2,Сountries!V:Z,5,0) -> 🇮🇸
A3: 2 | B3: Europe | C3: 🇦🇹 | D3: Austria | E3: 1.124 | H3: =VLOOKUP(D3,Сountries!V:Z,2,0) -> Europe | I3: =VLOOKUP(D3,Сountries!V:Z,5,0) -> 🇦🇹
A4: 3 | B4: Europe | C4: 🇮🇪 | D4: Ireland | E4: 1.124 | H4: =VLOOKUP(D4,Сountries!V:Z,2,0) -> Europe | I4: =VLOOKUP(D4,Сountries!V:Z,5,0) -> 🇮🇪
A5: 4 | B5: Australia and New Zealand | C5: 🇳🇿 | D5: New Zealand | E5: 1.323 | H5: =VLOOKUP(D5,Сountries!V:Z,2,0) -> Australia and New Zealand | I5: =VLOOKUP(D5,Сountries!V:Z,5,0) -> 🇳🇿
A6: 5 | B6: Asia | C6: 🇸🇬 | D6: Singapore | E6: 1.339 | H6: =VLOOKUP(D6,Сountries!V:Z,2,0) -> Asia | I6: =VLOOKUP(D6,Сountries!V:Z,5,0) -> 🇸🇬
A7: 6 | B7: Europe | C7: 🇨🇭 | D7: Switzerland | E7: 1.35 | H7: =VLOOKUP(D7,Сountries!V:Z,2,0) -> Europe | I7: =VLOOKUP(D7,Сountries!V:Z,5,0) -> 🇨🇭
A8: 7 | B8: Europe | C8: 🇵🇹 | D8: Portugal | E8: 1.372 | H8: =VLOOKUP(D8,Сountries!V:Z,2,0) -> Europe | I8: =VLOOKUP(D8,Сountries!V:Z,5,0) -> 🇵🇹
A9: 8 | B9: Europe | C9: 🇩🇰 | D9: Denmark | E9: 1.382 | H9: =VLOOKUP(D9,Сountries!V:Z,2,0) -> Europe | I9: =VLOOKUP(D9,Сountries!V:Z,5,0) -> 🇩🇰
A10: 9 | B10: Europe | C10: 🇸🇮 | D10: Slovenia | E10: 1.395 | H10: =VLOOKUP(D10,Сountries!V:Z,2,0) -> Europe | I10: =VLOOKUP(D10,Сountries!V:Z,5,0) -> 🇸🇮
A11: 10 | B11: Asia | C11: 🇲🇾 | D11: Malaysia | E11: 1.427 | H11: =VLOOKUP(D11,Сountries!V:Z,2,0) -> Asia | I11: =VLOOKUP(D11,Сountries!V:Z,5,0) -> 🇲🇾
A12: 11 | B12: America | C12: 🇨🇦 | D12: Canada | E12: 1.449 | H12: =VLOOKUP(D12,Сountries!V:Z,2,0) -> America | I12: =VLOOKUP(D12,Сountries!V:Z,5,0) -> 🇨🇦
A13: 12 | B13: Europe | C13: 🇨🇿 | D13: Czech Republic | E13: 1.459 | H13: =VLOOKUP(D13,Сountries!V:Z,2,0) -> Europe | I13: =VLOOKUP(D13,Сountries!V:Z,5,0) -> 🇨🇿
... A163: 162 | B163: Asia | C163: 🇾🇪 | D163: Yemen | E163: 3.397 | H163: =VLOOKUP(D163,Сountries!V:Z,2,0) -> Asia | I163: =VLOOKUP(D163,Сountries!V:Z,5,0) -> 🇾🇪
